[2024-04-29T09:22:13.918+0000] {local_task_job_runner.py:120} INFO - ::group::Pre task execution logs
[2024-04-29T09:22:13.929+0000] {taskinstance.py:2073} INFO - Dependencies all met for dep_context=non-requeueable deps ti=<TaskInstance: etl_for_open_weather.run_etl scheduled__2024-04-29T02:34:00+00:00 [queued]>
[2024-04-29T09:22:13.934+0000] {taskinstance.py:2073} INFO - Dependencies all met for dep_context=requeueable deps ti=<TaskInstance: etl_for_open_weather.run_etl scheduled__2024-04-29T02:34:00+00:00 [queued]>
[2024-04-29T09:22:13.935+0000] {taskinstance.py:2303} INFO - Starting attempt 1 of 2
[2024-04-29T09:22:13.944+0000] {taskinstance.py:2327} INFO - Executing <Task(PythonOperator): run_etl> on 2024-04-29 02:34:00+00:00
[2024-04-29T09:22:13.949+0000] {warnings.py:110} WARNING - /home/***/.local/lib/python3.12/site-packages/***/task/task_runner/standard_task_runner.py:61: DeprecationWarning: This process (pid=1314) is multi-threaded, use of fork() may lead to deadlocks in the child.
  pid = os.fork()

[2024-04-29T09:22:13.951+0000] {standard_task_runner.py:63} INFO - Started process 1326 to run task
[2024-04-29T09:22:13.951+0000] {standard_task_runner.py:90} INFO - Running: ['***', 'tasks', 'run', 'etl_for_open_weather', 'run_etl', 'scheduled__2024-04-29T02:34:00+00:00', '--job-id', '288', '--raw', '--subdir', 'DAGS_FOLDER/open_weather.py', '--cfg-path', '/tmp/tmplrw8ed2d']
[2024-04-29T09:22:13.952+0000] {standard_task_runner.py:91} INFO - Job 288: Subtask run_etl
[2024-04-29T09:22:13.988+0000] {task_command.py:426} INFO - Running <TaskInstance: etl_for_open_weather.run_etl scheduled__2024-04-29T02:34:00+00:00 [running]> on host ce94facc171a
[2024-04-29T09:22:14.047+0000] {taskinstance.py:2644} INFO - Exporting env vars: AIRFLOW_CTX_DAG_OWNER='***' AIRFLOW_CTX_DAG_ID='etl_for_open_weather' AIRFLOW_CTX_TASK_ID='run_etl' AIRFLOW_CTX_EXECUTION_DATE='2024-04-29T02:34:00+00:00' AIRFLOW_CTX_TRY_NUMBER='1' AIRFLOW_CTX_DAG_RUN_ID='scheduled__2024-04-29T02:34:00+00:00'
[2024-04-29T09:22:14.049+0000] {taskinstance.py:430} INFO - ::endgroup::
[2024-04-29T09:22:14.049+0000] {taskinstance.py:441} INFO - ::group::Post task execution logs
[2024-04-29T09:22:14.050+0000] {taskinstance.py:2890} ERROR - Task failed with exception
Traceback (most recent call last):
  File "/home/airflow/.local/lib/python3.12/site-packages/airflow/models/taskinstance.py", line 465, in _execute_task
    result = _execute_callable(context=context, **execute_callable_kwargs)
             ^^^^^^^^^^^^^^^^^^^^^^^^^^^^^^^^^^^^^^^^^^^^^^^^^^^^^^^^^^^^^
  File "/home/airflow/.local/lib/python3.12/site-packages/airflow/models/taskinstance.py", line 432, in _execute_callable
    return execute_callable(context=context, **execute_callable_kwargs)
           ^^^^^^^^^^^^^^^^^^^^^^^^^^^^^^^^^^^^^^^^^^^^^^^^^^^^^^^^^^^^
  File "/home/airflow/.local/lib/python3.12/site-packages/airflow/models/baseoperator.py", line 400, in wrapper
    return func(self, *args, **kwargs)
           ^^^^^^^^^^^^^^^^^^^^^^^^^^^
  File "/home/airflow/.local/lib/python3.12/site-packages/airflow/operators/python.py", line 235, in execute
    return_value = self.execute_callable()
                   ^^^^^^^^^^^^^^^^^^^^^^^
  File "/home/airflow/.local/lib/python3.12/site-packages/airflow/operators/python.py", line 252, in execute_callable
    return self.python_callable(*self.op_args, **self.op_kwargs)
           ^^^^^^^^^^^^^^^^^^^^^^^^^^^^^^^^^^^^^^^^^^^^^^^^^^^^^
  File "/opt/airflow/dags/open_weather.py", line 18, in get_open_weather
    data=task_instance.xcom_pull(task_id='extract_data')
         ^^^^^^^^^^^^^^^^^^^^^^^^^^^^^^^^^^^^^^^^^^^^^^^
  File "/home/airflow/.local/lib/python3.12/site-packages/airflow/utils/session.py", line 79, in wrapper
    return func(*args, session=session, **kwargs)
           ^^^^^^^^^^^^^^^^^^^^^^^^^^^^^^^^^^^^^^
TypeError: TaskInstance.xcom_pull() got an unexpected keyword argument 'task_id'
[2024-04-29T09:22:14.059+0000] {taskinstance.py:1205} INFO - Marking task as UP_FOR_RETRY. dag_id=etl_for_open_weather, task_id=run_etl, execution_date=20240429T023400, start_date=20240429T092213, end_date=20240429T092214
[2024-04-29T09:22:14.068+0000] {standard_task_runner.py:110} ERROR - Failed to execute job 288 for task run_etl (TaskInstance.xcom_pull() got an unexpected keyword argument 'task_id'; 1326)
[2024-04-29T09:22:14.084+0000] {local_task_job_runner.py:240} INFO - Task exited with return code 1
[2024-04-29T09:22:14.096+0000] {taskinstance.py:3482} INFO - 0 downstream tasks scheduled from follow-on schedule check
[2024-04-29T09:22:14.098+0000] {local_task_job_runner.py:222} INFO - ::endgroup::
