[2024-04-29T07:21:28.802+0000] {local_task_job_runner.py:120} INFO - ::group::Pre task execution logs
[2024-04-29T07:21:28.826+0000] {taskinstance.py:2073} INFO - Dependencies all met for dep_context=non-requeueable deps ti=<TaskInstance: etl_for_open_weather.transform_load_weather_data scheduled__2024-04-29T00:16:00+00:00 [queued]>
[2024-04-29T07:21:28.837+0000] {taskinstance.py:2073} INFO - Dependencies all met for dep_context=requeueable deps ti=<TaskInstance: etl_for_open_weather.transform_load_weather_data scheduled__2024-04-29T00:16:00+00:00 [queued]>
[2024-04-29T07:21:28.838+0000] {taskinstance.py:2303} INFO - Starting attempt 1 of 2
[2024-04-29T07:21:28.854+0000] {taskinstance.py:2327} INFO - Executing <Task(PythonOperator): transform_load_weather_data> on 2024-04-29 00:16:00+00:00
[2024-04-29T07:21:28.865+0000] {warnings.py:110} WARNING - /home/***/.local/lib/python3.12/site-packages/***/task/task_runner/standard_task_runner.py:61: DeprecationWarning: This process (pid=474) is multi-threaded, use of fork() may lead to deadlocks in the child.
  pid = os.fork()

[2024-04-29T07:21:28.866+0000] {standard_task_runner.py:63} INFO - Started process 509 to run task
[2024-04-29T07:21:28.870+0000] {standard_task_runner.py:90} INFO - Running: ['***', 'tasks', 'run', 'etl_for_open_weather', 'transform_load_weather_data', 'scheduled__2024-04-29T00:16:00+00:00', '--job-id', '36', '--raw', '--subdir', 'DAGS_FOLDER/open_weather.py', '--cfg-path', '/tmp/tmpp2y_z2_p']
[2024-04-29T07:21:28.872+0000] {standard_task_runner.py:91} INFO - Job 36: Subtask transform_load_weather_data
[2024-04-29T07:21:28.944+0000] {task_command.py:426} INFO - Running <TaskInstance: etl_for_open_weather.transform_load_weather_data scheduled__2024-04-29T00:16:00+00:00 [running]> on host 6dbc7f679521
[2024-04-29T07:21:29.060+0000] {taskinstance.py:2644} INFO - Exporting env vars: AIRFLOW_CTX_DAG_OWNER='***' AIRFLOW_CTX_DAG_ID='etl_for_open_weather' AIRFLOW_CTX_TASK_ID='transform_load_weather_data' AIRFLOW_CTX_EXECUTION_DATE='2024-04-29T00:16:00+00:00' AIRFLOW_CTX_TRY_NUMBER='1' AIRFLOW_CTX_DAG_RUN_ID='scheduled__2024-04-29T00:16:00+00:00'
[2024-04-29T07:21:29.063+0000] {taskinstance.py:430} INFO - ::endgroup::
[2024-04-29T07:21:29.065+0000] {taskinstance.py:441} INFO - ::group::Post task execution logs
[2024-04-29T07:21:29.066+0000] {taskinstance.py:2890} ERROR - Task failed with exception
Traceback (most recent call last):
  File "/home/airflow/.local/lib/python3.12/site-packages/airflow/models/taskinstance.py", line 465, in _execute_task
    result = _execute_callable(context=context, **execute_callable_kwargs)
             ^^^^^^^^^^^^^^^^^^^^^^^^^^^^^^^^^^^^^^^^^^^^^^^^^^^^^^^^^^^^^
  File "/home/airflow/.local/lib/python3.12/site-packages/airflow/models/taskinstance.py", line 432, in _execute_callable
    return execute_callable(context=context, **execute_callable_kwargs)
           ^^^^^^^^^^^^^^^^^^^^^^^^^^^^^^^^^^^^^^^^^^^^^^^^^^^^^^^^^^^^
  File "/home/airflow/.local/lib/python3.12/site-packages/airflow/models/baseoperator.py", line 400, in wrapper
    return func(self, *args, **kwargs)
           ^^^^^^^^^^^^^^^^^^^^^^^^^^^
  File "/home/airflow/.local/lib/python3.12/site-packages/airflow/operators/python.py", line 235, in execute
    return_value = self.execute_callable()
                   ^^^^^^^^^^^^^^^^^^^^^^^
  File "/home/airflow/.local/lib/python3.12/site-packages/airflow/operators/python.py", line 252, in execute_callable
    return self.python_callable(*self.op_args, **self.op_kwargs)
           ^^^^^^^^^^^^^^^^^^^^^^^^^^^^^^^^^^^^^^^^^^^^^^^^^^^^^
TypeError: get_open_weather() missing 1 required positional argument: 'task_'
[2024-04-29T07:21:29.079+0000] {taskinstance.py:1205} INFO - Marking task as UP_FOR_RETRY. dag_id=etl_for_open_weather, task_id=transform_load_weather_data, execution_date=20240429T001600, start_date=20240429T072128, end_date=20240429T072129
[2024-04-29T07:21:29.098+0000] {standard_task_runner.py:110} ERROR - Failed to execute job 36 for task transform_load_weather_data (get_open_weather() missing 1 required positional argument: 'task_'; 509)
[2024-04-29T07:21:29.120+0000] {local_task_job_runner.py:240} INFO - Task exited with return code 1
[2024-04-29T07:21:29.142+0000] {taskinstance.py:3482} INFO - 0 downstream tasks scheduled from follow-on schedule check
[2024-04-29T07:21:29.145+0000] {local_task_job_runner.py:222} INFO - ::endgroup::
